<?xml version="1.0" ?>
<!-- =================================================================================== -->
<!-- |    This document was autogenerated by xacro from xacro/mi_robot.urdf.xacro      | -->
<!-- |    EDITING THIS FILE BY HAND IS NOT RECOMMENDED                                 | -->
<!-- =================================================================================== -->
<robot name="mi_robot">
  <!-- Chasis -->
  <link name="base_link">
    <visual>
      <geometry>
        <box size="0.265 0.094 0.073"/>
      </geometry>
      <origin rpy="0 0 0" xyz="0 0 0.015"/>
      <material name="gray">
        <color rgba="0.5 0.5 0.5 1"/>
      </material>
    </visual>
    <collision>
      <geometry>
        <box size="0.265 0.094 0.073"/>
      </geometry>
      <origin rpy="0 0 0" xyz="0 0 0.015"/>
    </collision>
    <inertial>
      <origin rpy="0 0 0" xyz="0 0 0.015"/>
      <mass value="0.67"/>
      <inertia ixx="0.0007908791666666667" ixy="0" ixz="0" iyy="0.004218431666666667" iyz="0" izz="0.004414239166666668"/>
    </inertial>
  </link>
  <!-- Dummy root link to avoid KDL warning about inertia on root link -->
  <link name="robot_root">
    <!-- intentionally no inertial element here; KDL does not support inertia on the root link -->
  </link>
  <joint name="robot_root_joint" type="fixed">
    <parent link="robot_root"/>
    <child link="base_link"/>
    <origin rpy="0 0 0" xyz="0 0 0"/>
  </joint>
  <link name="wheel_fl_link">
    <visual>
      <origin rpy="1.5707963267948966 0 0" xyz="0 0 0"/>
      <geometry>
        <cylinder length="0.028" radius="0.0325"/>
      </geometry>
      <material name="black">
        <color rgba="0 0 0 1"/>
      </material>
    </visual>
    <collision>
      <origin rpy="1.5707963267948966 0 0" xyz="0 0 0"/>
      <geometry>
        <cylinder length="0.028" radius="0.0325"/>
      </geometry>
    </collision>
    <inertial>
      <origin rpy="1.5707963267948966 0 0" xyz="0 0 0"/>
      <mass value="0.032"/>
      <inertia ixx="1.0540666666666667e-05" ixy="0" ixz="0" iyy="1.0540666666666667e-05" iyz="0" izz="1.6900000000000004e-05"/>
    </inertial>
  </link>
  <joint name="wheel_fl_joint" type="continuous">
    <parent link="base_link"/>
    <child link="wheel_fl_link"/>
    <origin rpy="0 0 0" xyz="0.055 0.061 -0.009125"/>
    <axis xyz="0 1 0"/>
    <limit effort="1.0" velocity="30"/>
  </joint>
  <link name="wheel_fr_link">
    <visual>
      <origin rpy="1.5707963267948966 0 0" xyz="0 0 0"/>
      <geometry>
        <cylinder length="0.028" radius="0.0325"/>
      </geometry>
      <material name="black">
        <color rgba="0 0 0 1"/>
      </material>
    </visual>
    <collision>
      <origin rpy="1.5707963267948966 0 0" xyz="0 0 0"/>
      <geometry>
        <cylinder length="0.028" radius="0.0325"/>
      </geometry>
    </collision>
    <inertial>
      <origin rpy="1.5707963267948966 0 0" xyz="0 0 0"/>
      <mass value="0.032"/>
      <inertia ixx="1.0540666666666667e-05" ixy="0" ixz="0" iyy="1.0540666666666667e-05" iyz="0" izz="1.6900000000000004e-05"/>
    </inertial>
  </link>
  <joint name="wheel_fr_joint" type="continuous">
    <parent link="base_link"/>
    <child link="wheel_fr_link"/>
    <origin rpy="0 0 0" xyz="0.055 -0.061 -0.009125"/>
    <axis xyz="0 1 0"/>
    <limit effort="1.0" velocity="30"/>
  </joint>
  <link name="wheel_rl_link">
    <visual>
      <origin rpy="1.5707963267948966 0 0" xyz="0 0 0"/>
      <geometry>
        <cylinder length="0.028" radius="0.0325"/>
      </geometry>
      <material name="black">
        <color rgba="0 0 0 1"/>
      </material>
    </visual>
    <collision>
      <origin rpy="1.5707963267948966 0 0" xyz="0 0 0"/>
      <geometry>
        <cylinder length="0.028" radius="0.0325"/>
      </geometry>
    </collision>
    <inertial>
      <origin rpy="1.5707963267948966 0 0" xyz="0 0 0"/>
      <mass value="0.032"/>
      <inertia ixx="1.0540666666666667e-05" ixy="0" ixz="0" iyy="1.0540666666666667e-05" iyz="0" izz="1.6900000000000004e-05"/>
    </inertial>
  </link>
  <joint name="wheel_rl_joint" type="continuous">
    <parent link="base_link"/>
    <child link="wheel_rl_link"/>
    <origin rpy="0 0 0" xyz="-0.055 0.061 -0.009125"/>
    <axis xyz="0 1 0"/>
    <limit effort="1.0" velocity="30"/>
  </joint>
  <link name="wheel_rr_link">
    <visual>
      <origin rpy="1.5707963267948966 0 0" xyz="0 0 0"/>
      <geometry>
        <cylinder length="0.028" radius="0.0325"/>
      </geometry>
      <material name="black">
        <color rgba="0 0 0 1"/>
      </material>
    </visual>
    <collision>
      <origin rpy="1.5707963267948966 0 0" xyz="0 0 0"/>
      <geometry>
        <cylinder length="0.028" radius="0.0325"/>
      </geometry>
    </collision>
    <inertial>
      <origin rpy="1.5707963267948966 0 0" xyz="0 0 0"/>
      <mass value="0.032"/>
      <inertia ixx="1.0540666666666667e-05" ixy="0" ixz="0" iyy="1.0540666666666667e-05" iyz="0" izz="1.6900000000000004e-05"/>
    </inertial>
  </link>
  <joint name="wheel_rr_joint" type="continuous">
    <parent link="base_link"/>
    <child link="wheel_rr_link"/>
    <origin rpy="0 0 0" xyz="-0.055 -0.061 -0.009125"/>
    <axis xyz="0 1 0"/>
    <limit effort="1.0" velocity="30"/>
  </joint>
  <!-- LiDAR -->
  <link name="lidar_link">
    <visual>
      <geometry>
        <cylinder length="0.04" radius="0.035"/>
      </geometry>
      <material name="green">
        <color rgba="0 1 0 1"/>
      </material>
    </visual>
    <collision>
      <geometry>
        <cylinder length="0.04" radius="0.035"/>
      </geometry>
    </collision>
    <inertial>
      <origin rpy="0 0 0" xyz="0 0 0"/>
      <mass value="0.05"/>
      <inertia ixx="2.197916666666667e-05" ixy="0" ixz="0" iyy="2.197916666666667e-05" iyz="0" izz="3.0625000000000006e-05"/>
    </inertial>
  </link>
  <joint name="lidar_joint" type="fixed">
    <parent link="base_link"/>
    <child link="lidar_link"/>
    <origin rpy="0 0 0" xyz="0 0 0.056499999999999995"/>
  </joint>
  <!-- Sensor delantero -->
  <link name="sensor_front_link">
    <visual>
      <geometry>
        <cylinder length="0.02" radius="0.03"/>
      </geometry>
      <material name="red">
        <color rgba="1 0 0 1"/>
      </material>
    </visual>
  </link>
  <joint name="sensor_front_joint" type="fixed">
    <parent link="base_link"/>
    <child link="sensor_front_link"/>
    <origin rpy="0 0 0" xyz="0.1525 0 0.0365"/>
  </joint>
  <!-- Sensor trasero -->
  <link name="sensor_back_link">
    <visual>
      <geometry>
        <cylinder length="0.02" radius="0.03"/>
      </geometry>
      <material name="blue">
        <color rgba="0 0 1 1"/>
      </material>
    </visual>
  </link>
  <joint name="sensor_back_joint" type="fixed">
    <parent link="base_link"/>
    <child link="sensor_back_link"/>
    <origin rpy="0 0 0" xyz="-0.1525 0 0.0365"/>
  </joint>
  <!--gazebo-->
  <plugin filename="gz-sim-sensors-system" name="gz::sim::systems::Sensors">
    <render_engine>ogre2</render_engine>
  </plugin>
  <gazebo reference="lidar_link">
    <sensor name="laser" type="gpu_lidar">
      <!--if there's no gpu just use ray-->
      <pose> 0 0 0 0 0 0 </pose>
      <visualize> true </visualize>
      <update_rate> 10 </update_rate>
      <topic> scan </topic>
      <ray>
        <scan>
          <horizontal>
            <samples> 360 </samples>
            <resolution> 1 </resolution>
            <min_angle> -3.141592653589793 </min_angle>
            <max_angle> 3.141592653589793 </max_angle>
          </horizontal>
        </scan>
        <range>
          <min> 0.3 </min>
          <max> 12 </max>
          <resolution> 0.01 </resolution>
        </range>
      </ray>
    </sensor>
  </gazebo>
</robot>
